Workbook

Sheet Demand
A1: top | B1: mid | C1: low | D1: decimal | E1: changeable | F1: 변수설명 | G1: 참조지표 | H1: =I1-1 -> 2015 | I1: =J1-1 -> 2016 | J1: =K1-1 -> 2017 | K1: =L1-1 -> 2018 | L1: =M1-1 -> 2019 | M1: =N1-1 -> 2020 | N1: =O1-1 -> 2021 | O1: =P1-1 -> 2022 | P1: =Q1-1 -> 2023 | Q1: =ref!B4 -> 2024 | R1: =Q1+1 -> 2025 | S1: =R1+1 -> 2026 | T1: =S1+1 -> 2027 | U1: =T1+1 -> 2028 | V1: =U1+1 -> 2029 | W1: =V1+1 -> 2030 | X1: =W1+1 -> 2031 | Y1: =X1+1 -> 2032 | ... AU1: =AT1+1 -> 2054
A2: General Index | B2: Passenger Index | C2: Annual Passengers📝 | D2: float0 | E2: O | F2: 연간여객 | H2: =VLOOKUP($F2,raw_data!$1:$1048576,MATCH(H$1,raw_data!$1:$1,0),FALSE) -> 317549 | I2: =VLOOKUP($F2,raw_data!$1:$1048576,MATCH(I$1,raw_data!$1:$1,0),FALSE) -> 296385 | J2: =VLOOKUP($F2,raw_data!$1:$1048576,MATCH(J$1,raw_data!$1:$1,0),FALSE) -> 300529 | K2: =VLOOKUP($F2,raw_data!$1:$1048576,MATCH(K$1,raw_data!$1:$1,0),FALSE) -> 360857 | L2: =VLOOKUP($F2,raw_data!$1:$1048576,MATCH(L$1,raw_data!$1:$1,0),FALSE) -> 427585 | M2: =VLOOKUP($F2,raw_data!$1:$1048576,MATCH(M$1,raw_data!$1:$1,0),FALSE) -> 119957 | N2: =VLOOKUP($F2,raw_data!$1:$1048576,MATCH(N$1,raw_data!$1:$1,0),FALSE) -> 336251 | O2: =VLOOKUP($F2,raw_data!$1:$1048576,MATCH(O$1,raw_data!$1:$1,0),FALSE) -> 503019 | ... Q2: =VLOOKUP($F2,raw_data!$1:$1048576,MATCH(Q$1,raw_data!$1:$1,0),FALSE) -> 601530 | R2: 690661.64 | S2: 762316.79 | T2: 844425.68 | U2: 930926.7 | V2: 1025226.3 | W2: 1133823.9 | X2: 1230510.3 | Y2: 1338980.8 | Z2: 1465253.4 | AA2: 1606814.7 | AB2: 1765878.6 | AC2: 1915282.8 | AD2: 2065216.5 | AE2: 2216067.1 | AF2: 2367438.7 | AG2: 2516702.3 | AH2: 2668163 | AI2: 2819465.6 | AJ2: 2928179.3 | AK2: 3043999.2 | AL2: 3163819.4 | AM2: 3287901 | AN2: 3415977.5 | AO2: 3550247.8 | AP2: 3691036.5 | AQ2: 3834900.1 | AR2: 3986568 | AS2: 4144450 | AT2: 4306348.8 | AU2: 4476225.1
C3: International Passengers | D3: float0 | F3: International여객 | H3: =VLOOKUP($F3,raw_data!$1:$1048576,MATCH(H$1,raw_data!$1:$1,0),FALSE) -> 125299 | I3: =VLOOKUP($F3,raw_data!$1:$1048576,MATCH(I$1,raw_data!$1:$1,0),FALSE) -> 103500 | J3: =VLOOKUP($F3,raw_data!$1:$1048576,MATCH(J$1,raw_data!$1:$1,0),FALSE) -> 117081 | K3: =VLOOKUP($F3,raw_data!$1:$1048576,MATCH(K$1,raw_data!$1:$1,0),FALSE) -> 162463 | L3: =VLOOKUP($F3,raw_data!$1:$1048576,MATCH(L$1,raw_data!$1:$1,0),FALSE) -> 212440 | M3: =VLOOKUP($F3,raw_data!$1:$1048576,MATCH(M$1,raw_data!$1:$1,0),FALSE) -> 54451 | N3: =VLOOKUP($F3,raw_data!$1:$1048576,MATCH(N$1,raw_data!$1:$1,0),FALSE) -> 174174 | O3: =VLOOKUP($F3,raw_data!$1:$1048576,MATCH(O$1,raw_data!$1:$1,0),FALSE) -> 298727 | ... Q3: =VLOOKUP($F3,raw_data!$1:$1048576,MATCH(Q$1,raw_data!$1:$1,0),FALSE) -> 318069 | R3: =R2*R9 -> 363709.35 | S3: =S2*S9 -> 412526.08 | T3: =T2*T9 -> 460870.48 | U3: =U2*U9 -> 499127.63 | V3: =V2*V9 -> 549206.85 | W3: =W2*W9 -> 608952.56 | X3: =X2*X9 -> 663457.13 | Y3: =Y2*Y9 -> 721412.39 | ... AU3: =AU2*AU9 -> 2408019.4
C4: Domestic Passengers | D4: float0 | F4: Domestic여객 | H4: =VLOOKUP($F4,raw_data!$1:$1048576,MATCH(H$1,raw_data!$1:$1,0),FALSE) -> 192250 | I4: =VLOOKUP($F4,raw_data!$1:$1048576,MATCH(I$1,raw_data!$1:$1,0),FALSE) -> 192885 | J4: =VLOOKUP($F4,raw_data!$1:$1048576,MATCH(J$1,raw_data!$1:$1,0),FALSE) -> 183448 | K4: =VLOOKUP($F4,raw_data!$1:$1048576,MATCH(K$1,raw_data!$1:$1,0),FALSE) -> 198394 | L4: =VLOOKUP($F4,raw_data!$1:$1048576,MATCH(L$1,raw_data!$1:$1,0),FALSE) -> 215145 | M4: =VLOOKUP($F4,raw_data!$1:$1048576,MATCH(M$1,raw_data!$1:$1,0),FALSE) -> 65506 | N4: =VLOOKUP($F4,raw_data!$1:$1048576,MATCH(N$1,raw_data!$1:$1,0),FALSE) -> 162077 | O4: =VLOOKUP($F4,raw_data!$1:$1048576,MATCH(O$1,raw_data!$1:$1,0),FALSE) -> 204292 | ... Q4: =VLOOKUP($F4,raw_data!$1:$1048576,MATCH(Q$1,raw_data!$1:$1,0),FALSE) -> 283461 | R4: =R2-R3 -> 326952.29 | S4: =S2-S3 -> 349790.7 | T4: =T2-T3 -> 383555.2 | U4: =U2-U3 -> 431799.07 | V4: =V2-V3 -> 476019.46 | W4: =W2-W3 -> 524871.32 | X4: =X2-X3 -> 567053.21 | Y4: =Y2-Y3 -> 617568.46 | ... AU4: =AU2-AU3 -> 2068205.7
C5: Long_haul Passengers | D5: float0 | F5: Long_haul여객 | H5: =VLOOKUP($F5,raw_data!$1:$1048576,MATCH(H$1,raw_data!$1:$1,0),FALSE) -> 4469 | I5: =VLOOKUP($F5,raw_data!$1:$1048576,MATCH(I$1,raw_data!$1:$1,0),FALSE) -> 7174 | J5: =VLOOKUP($F5,raw_data!$1:$1048576,MATCH(J$1,raw_data!$1:$1,0),FALSE) -> 7308 | K5: =VLOOKUP($F5,raw_data!$1:$1048576,MATCH(K$1,raw_data!$1:$1,0),FALSE) -> 5646 | L5: =VLOOKUP($F5,raw_data!$1:$1048576,MATCH(L$1,raw_data!$1:$1,0),FALSE) -> 11025 | M5: =VLOOKUP($F5,raw_data!$1:$1048576,MATCH(M$1,raw_data!$1:$1,0),FALSE) -> 0 | N5: =VLOOKUP($F5,raw_data!$1:$1048576,MATCH(N$1,raw_data!$1:$1,0),FALSE) -> 0 | O5: =VLOOKUP($F5,raw_data!$1:$1048576,MATCH(O$1,raw_data!$1:$1,0),FALSE) -> 3387 | ... Q5: =VLOOKUP($F5,raw_data!$1:$1048576,MATCH(Q$1,raw_data!$1:$1,0),FALSE) -> 13587 | R5: =R2*R10 -> 14738.221 | S5: =S2*S10 -> 16267.29 | T5: =T2*T10 -> 18019.435 | U5: =U2*U10 -> 19865.304 | V5: =V2*V10 -> 21877.59 | W5: =W2*W10 -> 24194.984 | X5: =X2*X10 -> 26258.203 | Y5: =Y2*Y10 -> 28572.885 | ... AU5: =AU2*AU10 -> 95519.415
C6: Short_haul Passengers | D6: float0 | F6: Short_haul여객 | H6: =VLOOKUP($F6,raw_data!$1:$1048576,MATCH(H$1,raw_data!$1:$1,0),FALSE) -> 313080 | I6: =VLOOKUP($F6,raw_data!$1:$1048576,MATCH(I$1,raw_data!$1:$1,0),FALSE) -> 289211 | J6: =VLOOKUP($F6,raw_data!$1:$1048576,MATCH(J$1,raw_data!$1:$1,0),FALSE) -> 293221 | K6: =VLOOKUP($F6,raw_data!$1:$1048576,MATCH(K$1,raw_data!$1:$1,0),FALSE) -> 355211 | L6: =VLOOKUP($F6,raw_data!$1:$1048576,MATCH(L$1,raw_data!$1:$1,0),FALSE) -> 416560 | M6: =VLOOKUP($F6,raw_data!$1:$1048576,MATCH(M$1,raw_data!$1:$1,0),FALSE) -> 119957 | N6: =VLOOKUP($F6,raw_data!$1:$1048576,MATCH(N$1,raw_data!$1:$1,0),FALSE) -> 336251 | O6: =VLOOKUP($F6,raw_data!$1:$1048576,MATCH(O$1,raw_data!$1:$1,0),FALSE) -> 499632 | ... Q6: =VLOOKUP($F6,raw_data!$1:$1048576,MATCH(Q$1,raw_data!$1:$1,0),FALSE) -> 587943 | R6: =R2-R5 -> 675923.42 | S6: =S2-S5 -> 746049.5 | T6: =T2-T5 -> 826406.25 | U6: =U2-U5 -> 911061.39 | V6: =V2-V5 -> 1003348.7 | W6: =W2-W5 -> 1109628.9 | X6: =X2-X5 -> 1204252.1 | Y6: =Y2-Y5 -> 1310408 | ... AU6: =AU2-AU5 -> 4380705.7
C7: Normal Passengers | D7: float0 | F7: 정규여객 | H7: =VLOOKUP($F7,raw_data!$1:$1048576,MATCH(H$1,raw_data!$1:$1,0),FALSE) -> 317549 | I7: =VLOOKUP($F7,raw_data!$1:$1048576,MATCH(I$1,raw_data!$1:$1,0),FALSE) -> 296385 | J7: =VLOOKUP($F7,raw_data!$1:$1048576,MATCH(J$1,raw_data!$1:$1,0),FALSE) -> 300529 | K7: =VLOOKUP($F7,raw_data!$1:$1048576,MATCH(K$1,raw_data!$1:$1,0),FALSE) -> 360857 | L7: =VLOOKUP($F7,raw_data!$1:$1048576,MATCH(L$1,raw_data!$1:$1,0),FALSE) -> 427585 | M7: =VLOOKUP($F7,raw_data!$1:$1048576,MATCH(M$1,raw_data!$1:$1,0),FALSE) -> 119957 | N7: =VLOOKUP($F7,raw_data!$1:$1048576,MATCH(N$1,raw_data!$1:$1,0),FALSE) -> 336251 | O7: =VLOOKUP($F7,raw_data!$1:$1048576,MATCH(O$1,raw_data!$1:$1,0),FALSE) -> 503019 | ... Q7: =VLOOKUP($F7,raw_data!$1:$1048576,MATCH(Q$1,raw_data!$1:$1,0),FALSE) -> 601530 | R7: =R2*R11 -> 690661.64 | S7: =S2*S11 -> 762316.79 | T7: =T2*T11 -> 844425.68 | U7: =U2*U11 -> 930926.7 | V7: =V2*V11 -> 1025226.3 | W7: =W2*W11 -> 1133823.9 | X7: =X2*X11 -> 1230510.3 | Y7: =Y2*Y11 -> 1338980.8 | ... AU7: =AU2*AU11 -> 4476225.1
C8: Charter Passengers | D8: float0 | F8: 전세기여객 | H8: =VLOOKUP($F8,raw_data!$1:$1048576,MATCH(H$1,raw_data!$1:$1,0),FALSE) -> 0 | I8: =VLOOKUP($F8,raw_data!$1:$1048576,MATCH(I$1,raw_data!$1:$1,0),FALSE) -> 0 | J8: =VLOOKUP($F8,raw_data!$1:$1048576,MATCH(J$1,raw_data!$1:$1,0),FALSE) -> 0 | K8: =VLOOKUP($F8,raw_data!$1:$1048576,MATCH(K$1,raw_data!$1:$1,0),FALSE) -> 0 | L8: =VLOOKUP($F8,raw_data!$1:$1048576,MATCH(L$1,raw_data!$1:$1,0),FALSE) -> 0 | M8: =VLOOKUP($F8,raw_data!$1:$1048576,MATCH(M$1,raw_data!$1:$1,0),FALSE) -> 0 | N8: =VLOOKUP($F8,raw_data!$1:$1048576,MATCH(N$1,raw_data!$1:$1,0),FALSE) -> 0 | O8: =VLOOKUP($F8,raw_data!$1:$1048576,MATCH(O$1,raw_data!$1:$1,0),FALSE) -> 0 | ... Q8: =VLOOKUP($F8,raw_data!$1:$1048576,MATCH(Q$1,raw_data!$1:$1,0),FALSE) -> 0 | R8: =R2-R7 -> 0 | S8: =S2-S7 -> 0 | T8: =T2-T7 -> 0 | U8: =U2-U7 -> 0 | V8: =V2-V7 -> 0 | W8: =W2-W7 -> 0 | X8: =X2-X7 -> 0 | Y8: =Y2-Y7 -> 0 | ... AU8: =AU2-AU7 -> 0
C9: International Passengers(%)📝 | D9: percent0 | E9: O | G9: =IFERROR(SUMIF($H$145:$Q$145,"O",H9:Q9)/COUNTIFS($H$145:$Q$145,"O",H9:Q9,"<>0"),0) -> 0.49193929 | H9: =H3/H2 -> 0.39458162 | I9: =I3/I2 -> 0.34920796 | J9: =J3/J2 -> 0.38958304 | K9: =K3/K2 -> 0.45021435 | L9: =L3/L2 -> 0.49683689 | M9: =M3/M2 -> 0.45392099 | N9: =N3/N2 -> 0.51798805 | O9: =O3/O2 -> 0.59386822 | ... Q9: =Q3/Q2 -> 0.52876665 | R9: =AVERAGE(M9:Q9) -> 0.52661003 | S9: =AVERAGE(N9:R9) -> 0.54114784 | T9: =AVERAGE(O9:S9) -> 0.5457798 | U9: =AVERAGE(P9:T9) -> 0.53616211 | V9: =AVERAGE(Q9:U9) -> 0.53569329 | W9: =AVERAGE(R9:V9) -> 0.53707861 | X9: =AVERAGE(S9:W9) -> 0.53917233 | Y9: =AVERAGE(T9:X9) -> 0.53877723 | ... AU9: =AVERAGE(AP9:AT9) -> 0.53795763
C10: Longhaul Passengers(%)📝 | D10: percent0 | E10: O | G10: =IFERROR(SUMIF($H$145:$Q$145,"O",H10:Q10)/COUNTIFS($H$145:$Q$145,"O",H10:Q10,"<>0"),0) -> 0.021339279 | H10: =H5/H2 -> 0.014073419 | I10: =I5/I2 -> 0.024205004 | J10: =J5/J2 -> 0.024317121 | K10: =K5/K2 -> 0.015646087 | L10: =L5/L2 -> 0.025784347 | M10: =M5/M2 -> 0 | N10: =N5/N2 -> 0 | O10: =O5/O2 -> 0.0067333441 | ... Q10: =Q5/Q2 -> 0.022587402 | R10: =G10 -> 0.021339279 | S10: =R10 -> 0.021339279 | T10: =S10 -> 0.021339279 | U10: =T10 -> 0.021339279 | V10: =U10 -> 0.021339279 | W10: =V10 -> 0.021339279 | X10: =W10 -> 0.021339279 | Y10: =X10 -> 0.021339279 | Z10: =Y10 -> 0.021339279 | ... AU10: =AT10 -> 0.021339279
C11: Regular Passengers(%)📝 | D11: percent0 | E11: O | G11: =IFERROR(SUMIF($H$145:$Q$145,"O",H11:Q11)/COUNTIFS($H$145:$Q$145,"O",H11:Q11,"<>0"),0) -> 1 | H11: =H7/H2 -> 1 | I11: =I7/I2 -> 1 | J11: =J7/J2 -> 1 | K11: =K7/K2 -> 1 | L11: =L7/L2 -> 1 | M11: =M7/M2 -> 1 | N11: =N7/N2 -> 1 | O11: =O7/O2 -> 1 | ... Q11: =Q7/Q2 -> 1 | R11: =G11 -> 1 | S11: =R11 -> 1 | T11: =S11 -> 1 | U11: =T11 -> 1 | V11: =U11 -> 1 | W11: =V11 -> 1 | X11: =W11 -> 1 | Y11: =X11 -> 1 | Z11: =Y11 -> 1 | ... AU11: =AT11 -> 1
C12: Total Seats | D12: float0 | H12: =H13*H20 -> 372767 | I12: =I13*I20 -> 362139 | J12: =J13*J20 -> 377076 | K12: =K13*K20 -> 451047 | L12: =L13*L20 -> 538749 | M12: =M13*M20 -> 160120 | N12: =N13*N20 -> 412029 | O12: =O13*O20 -> 608138 | ... AU12: =AU13*AU20 -> 5698031.1
C13: Average Seats Per Aircraft | D13: float0 | F13: 대당좌석수 | H13: =VLOOKUP($F13,raw_data!$1:$1048576,MATCH(H$1,raw_data!$1:$1,0),FALSE) -> 131.48748 | I13: =VLOOKUP($F13,raw_data!$1:$1048576,MATCH(I$1,raw_data!$1:$1,0),FALSE) -> 130.68892 | J13: =VLOOKUP($F13,raw_data!$1:$1048576,MATCH(J$1,raw_data!$1:$1,0),FALSE) -> 124.61203 | K13: =VLOOKUP($F13,raw_data!$1:$1048576,MATCH(K$1,raw_data!$1:$1,0),FALSE) -> 161.60767 | L13: =VLOOKUP($F13,raw_data!$1:$1048576,MATCH(L$1,raw_data!$1:$1,0),FALSE) -> 166.74373 | M13: =VLOOKUP($F13,raw_data!$1:$1048576,MATCH(M$1,raw_data!$1:$1,0),FALSE) -> 164.56321 | N13: =VLOOKUP($F13,raw_data!$1:$1048576,MATCH(N$1,raw_data!$1:$1,0),FALSE) -> 166.27482 | O13: =VLOOKUP($F13,raw_data!$1:$1048576,MATCH(O$1,raw_data!$1:$1,0),FALSE) -> 152.14861 | ... Q13: =VLOOKUP($F13,raw_data!$1:$1048576,MATCH(Q$1,raw_data!$1:$1,0),FALSE) -> 158.01924 | R13: =SUMPRODUCT(R37:R40,R25:R28) -> 162.33381 | S13: =SUMPRODUCT(S37:S40,S25:S28) -> 162.33381 | T13: =SUMPRODUCT(T37:T40,T25:T28) -> 162.33381 | U13: =SUMPRODUCT(U37:U40,U25:U28) -> 162.33381 | V13: =SUMPRODUCT(V37:V40,V25:V28) -> 162.33381 | W13: =SUMPRODUCT(W37:W40,W25:W28) -> 162.33381 | X13: =SUMPRODUCT(X37:X40,X25:X28) -> 162.33381 | Y13: =SUMPRODUCT(Y37:Y40,Y25:Y28) -> 162.33381 | ... AU13: =SUMPRODUCT(AU37:AU40,AU25:AU28) -> 162.33381
C14: Load Factor(%)📝 | D14: percent0 | E14: O | F14: 탑승율 | G14: =SUMIF($H$146:$Q$146,"O",H14:Q14)/COUNTIFS($H$146:$Q$146,"O",H14:Q14,"<>0") -> 0.78557401 | H14: =VLOOKUP($F14,raw_data!$1:$1048576,MATCH(H$1,raw_data!$1:$1,0),FALSE) -> 0.85186993 | I14: =VLOOKUP($F14,raw_data!$1:$1048576,MATCH(I$1,raw_data!$1:$1,0),FALSE) -> 0.81842884 | J14: =VLOOKUP($F14,raw_data!$1:$1048576,MATCH(J$1,raw_data!$1:$1,0),FALSE) -> 0.79699848 | K14: =VLOOKUP($F14,raw_data!$1:$1048576,MATCH(K$1,raw_data!$1:$1,0),FALSE) -> 0.80004301 | L14: =VLOOKUP($F14,raw_data!$1:$1048576,MATCH(L$1,raw_data!$1:$1,0),FALSE) -> 0.79366273 | M14: =VLOOKUP($F14,raw_data!$1:$1048576,MATCH(M$1,raw_data!$1:$1,0),FALSE) -> 0.74916937 | N14: =VLOOKUP($F14,raw_data!$1:$1048576,MATCH(N$1,raw_data!$1:$1,0),FALSE) -> 0.81608576 | O14: =VLOOKUP($F14,raw_data!$1:$1048576,MATCH(O$1,raw_data!$1:$1,0),FALSE) -> 0.82714614 | ... Q14: =VLOOKUP($F14,raw_data!$1:$1048576,MATCH(Q$1,raw_data!$1:$1,0),FALSE) -> 0.76301629 | R14: =G14 -> 0.78557401 | S14: =R14 -> 0.78557401 | T14: =S14 -> 0.78557401 | U14: =T14 -> 0.78557401 | V14: =U14 -> 0.78557401 | W14: =V14 -> 0.78557401 | X14: =W14 -> 0.78557401 | Y14: =X14 -> 0.78557401 | Z14: =Y14 -> 0.78557401 | ... AU14: =AT14 -> 0.78557401
C15: Average Passengers Per Aircraft | D15: float0 | F15: 대당여객 | H15: =VLOOKUP($F15,raw_data!$1:$1048576,MATCH(H$1,raw_data!$1:$1,0),FALSE) -> 112.01023 | I15: =VLOOKUP($F15,raw_data!$1:$1048576,MATCH(I$1,raw_data!$1:$1,0),FALSE) -> 106.95958 | J15: =VLOOKUP($F15,raw_data!$1:$1048576,MATCH(J$1,raw_data!$1:$1,0),FALSE) -> 99.315598 | K15: =VLOOKUP($F15,raw_data!$1:$1048576,MATCH(K$1,raw_data!$1:$1,0),FALSE) -> 129.29308 | L15: =VLOOKUP($F15,raw_data!$1:$1048576,MATCH(L$1,raw_data!$1:$1,0),FALSE) -> 132.33829 | M15: =VLOOKUP($F15,raw_data!$1:$1048576,MATCH(M$1,raw_data!$1:$1,0),FALSE) -> 123.28571 | N15: =VLOOKUP($F15,raw_data!$1:$1048576,MATCH(N$1,raw_data!$1:$1,0),FALSE) -> 135.69451 | O15: =VLOOKUP($F15,raw_data!$1:$1048576,MATCH(O$1,raw_data!$1:$1,0),FALSE) -> 125.84914 | ... Q15: =VLOOKUP($F15,raw_data!$1:$1048576,MATCH(Q$1,raw_data!$1:$1,0),FALSE) -> 120.57126 | R15: =R13*R14 -> 127.52522 | S15: =S13*S14 -> 127.52522 | T15: =T13*T14 -> 127.52522 | U15: =U13*U14 -> 127.52522 | V15: =V13*V14 -> 127.52522 | W15: =W13*W14 -> 127.52522 | X15: =X13*X14 -> 127.52522 | Y15: =Y13*Y14 -> 127.52522 | ... AU15: =AU13*AU14 -> 127.52522
C16: Annual Transfer Passengers | D16: float0 | F16: 연간환승승객 | H16: =VLOOKUP($F16,raw_data!$1:$1048576,MATCH(H$1,raw_data!$1:$1,0),FALSE) -> 18596 | I16: =VLOOKUP($F16,raw_data!$1:$1048576,MATCH(I$1,raw_data!$1:$1,0),FALSE) -> 14375 | J16: =VLOOKUP($F16,raw_data!$1:$1048576,MATCH(J$1,raw_data!$1:$1,0),FALSE) -> 11324 | K16: =VLOOKUP($F16,raw_data!$1:$1048576,MATCH(K$1,raw_data!$1:$1,0),FALSE) -> 9561 | L16: =VLOOKUP($F16,raw_data!$1:$1048576,MATCH(L$1,raw_data!$1:$1,0),FALSE) -> 10501 | M16: =VLOOKUP($F16,raw_data!$1:$1048576,MATCH(M$1,raw_data!$1:$1,0),FALSE) -> 1959 | N16: =VLOOKUP($F16,raw_data!$1:$1048576,MATCH(N$1,raw_data!$1:$1,0),FALSE) -> 11275 | O16: =VLOOKUP($F16,raw_data!$1:$1048576,MATCH(O$1,raw_data!$1:$1,0),FALSE) -> 16586 | ... Q16: =VLOOKUP($F16,raw_data!$1:$1048576,MATCH(Q$1,raw_data!$1:$1,0),FALSE) -> 18303 | R16: =R2*R17 -> 18758.722 | S16: =S2*S17 -> 20704.913 | T16: =T2*T17 -> 22935.032 | U16: =U2*U17 -> 25284.444 | V16: =V2*V17 -> 27845.67 | W16: =W2*W17 -> 30795.235 | X16: =X2*X17 -> 33421.288 | Y16: =Y2*Y17 -> 36367.402 | ... AU16: =AU2*AU17 -> 121576.56
C17: Transfer Rate(%)📝 | D17: percent0 | E17: O | F17: 환승율 | G17: =SUMIF($H$147:$Q$147,"O",H17:Q17)/COUNTIFS($H$147:$Q$147,"O",H17:Q17,"<>0") -> 0.02716051 | H17: =VLOOKUP($F17,raw_data!$1:$1048576,MATCH(H$1,raw_data!$1:$1,0),FALSE) -> 0.058561041 | I17: =VLOOKUP($F17,raw_data!$1:$1048576,MATCH(I$1,raw_data!$1:$1,0),FALSE) -> 0.048501105 | J17: =VLOOKUP($F17,raw_data!$1:$1048576,MATCH(J$1,raw_data!$1:$1,0),FALSE) -> 0.037680224 | K17: =VLOOKUP($F17,raw_data!$1:$1048576,MATCH(K$1,raw_data!$1:$1,0),FALSE) -> 0.02649526 | L17: =VLOOKUP($F17,raw_data!$1:$1048576,MATCH(L$1,raw_data!$1:$1,0),FALSE) -> 0.02455886 | M17: =VLOOKUP($F17,raw_data!$1:$1048576,MATCH(M$1,raw_data!$1:$1,0),FALSE) -> 0.016330852 | N17: =VLOOKUP($F17,raw_data!$1:$1048576,MATCH(N$1,raw_data!$1:$1,0),FALSE) -> 0.033531499 | O17: =VLOOKUP($F17,raw_data!$1:$1048576,MATCH(O$1,raw_data!$1:$1,0),FALSE) -> 0.03297291 | ... Q17: =VLOOKUP($F17,raw_data!$1:$1048576,MATCH(Q$1,raw_data!$1:$1,0),FALSE) -> 0.03042741 | R17: =G17 -> 0.02716051 | S17: =R17 -> 0.02716051 | T17: =S17 -> 0.02716051 | U17: =T17 -> 0.02716051 | V17: =U17 -> 0.02716051 | W17: =V17 -> 0.02716051 | X17: =W17 -> 0.02716051 | Y17: =X17 -> 0.02716051 | Z17: =Y17 -> 0.02716051 | ... AU17: =AT17 -> 0.02716051
C18: Average Crew Per Aircraft | D18: float0 | F18: 대당승무원 | H18: =VLOOKUP($F18,raw_data!$1:$1048576,MATCH(H$1,raw_data!$1:$1,0),FALSE) -> 7.1513228 | I18: =VLOOKUP($F18,raw_data!$1:$1048576,MATCH(I$1,raw_data!$1:$1,0),FALSE) -> 6.7513533 | J18: =VLOOKUP($F18,raw_data!$1:$1048576,MATCH(J$1,raw_data!$1:$1,0),FALSE) -> 6.1996034 | K18: =VLOOKUP($F18,raw_data!$1:$1048576,MATCH(K$1,raw_data!$1:$1,0),FALSE) -> 8.4632748 | L18: =VLOOKUP($F18,raw_data!$1:$1048576,MATCH(L$1,raw_data!$1:$1,0),FALSE) -> 8.4020427 | M18: =VLOOKUP($F18,raw_data!$1:$1048576,MATCH(M$1,raw_data!$1:$1,0),FALSE) -> 7.995889 | N18: =VLOOKUP($F18,raw_data!$1:$1048576,MATCH(N$1,raw_data!$1:$1,0),FALSE) -> 8.653753 | O18: =VLOOKUP($F18,raw_data!$1:$1048576,MATCH(O$1,raw_data!$1:$1,0),FALSE) -> 8.1341006 | ... Q18: =VLOOKUP($F18,raw_data!$1:$1048576,MATCH(Q$1,raw_data!$1:$1,0),FALSE) -> 7.702746 | R18: =IFERROR(SUMPRODUCT(R29:R32,R51:R54)/SUM(R29:R32),0) -> 8.1967823 | S18: =IFERROR(SUMPRODUCT(S29:S32,S51:S54)/SUM(S29:S32),0) -> 8.1967823 | T18: =IFERROR(SUMPRODUCT(T29:T32,T51:T54)/SUM(T29:T32),0) -> 8.1967823 | U18: =IFERROR(SUMPRODUCT(U29:U32,U51:U54)/SUM(U29:U32),0) -> 8.1967823 | V18: =IFERROR(SUMPRODUCT(V29:V32,V51:V54)/SUM(V29:V32),0) -> 8.1967823 | W18: =IFERROR(SUMPRODUCT(W29:W32,W51:W54)/SUM(W29:W32),0) -> 8.1967823 | X18: =IFERROR(SUMPRODUCT(X29:X32,X51:X54)/SUM(X29:X32),0) -> 8.1967823 | Y18: =IFERROR(SUMPRODUCT(Y29:Y32,Y51:Y54)/SUM(Y29:Y32),0) -> 8.1967823 | ... AU18: =IFERROR(SUMPRODUCT(AU29:AU32,AU51:AU54)/SUM(AU29:AU32),0) -> 8.1967823
C19: Crew Ratio(%) | D19: percent0 | F19: 승무원비율 | H19: =VLOOKUP($F19,raw_data!$1:$1048576,MATCH(H$1,raw_data!$1:$1,0),FALSE) -> 0.063845265 | I19: =VLOOKUP($F19,raw_data!$1:$1048576,MATCH(I$1,raw_data!$1:$1,0),FALSE) -> 0.063120603 | J19: =VLOOKUP($F19,raw_data!$1:$1048576,MATCH(J$1,raw_data!$1:$1,0),FALSE) -> 0.06242326 | K19: =VLOOKUP($F19,raw_data!$1:$1048576,MATCH(K$1,raw_data!$1:$1,0),FALSE) -> 0.065458062 | L19: =VLOOKUP($F19,raw_data!$1:$1048576,MATCH(L$1,raw_data!$1:$1,0),FALSE) -> 0.063489131 | M19: =VLOOKUP($F19,raw_data!$1:$1048576,MATCH(M$1,raw_data!$1:$1,0),FALSE) -> 0.064856574 | N19: =VLOOKUP($F19,raw_data!$1:$1048576,MATCH(N$1,raw_data!$1:$1,0),FALSE) -> 0.063773788 | O19: =VLOOKUP($F19,raw_data!$1:$1048576,MATCH(O$1,raw_data!$1:$1,0),FALSE) -> 0.064633741 | ... Q19: =VLOOKUP($F19,raw_data!$1:$1048576,MATCH(Q$1,raw_data!$1:$1,0),FALSE) -> 0.063885425 | R19: =IFERROR(R18/R15,0) -> 0.064275774 | S19: =IFERROR(S18/S15,0) -> 0.064275774 | T19: =IFERROR(T18/T15,0) -> 0.064275774 | U19: =IFERROR(U18/U15,0) -> 0.064275774 | V19: =IFERROR(V18/V15,0) -> 0.064275774 | W19: =IFERROR(W18/W15,0) -> 0.064275774 | X19: =IFERROR(X18/X15,0) -> 0.064275774 | Y19: =IFERROR(Y18/Y15,0) -> 0.064275774 | ... AU19: =IFERROR(AU18/AU15,0) -> 0.064275774
B20: Flight Index | C20: Annual Movements | D20: float0 | F20: 연간운항 | H20: =VLOOKUP($F20,raw_data!$1:$1048576,MATCH(H$1,raw_data!$1:$1,0),FALSE) -> 2835 | I20: =VLOOKUP($F20,raw_data!$1:$1048576,MATCH(I$1,raw_data!$1:$1,0),FALSE) -> 2771 | J20: =VLOOKUP($F20,raw_data!$1:$1048576,MATCH(J$1,raw_data!$1:$1,0),FALSE) -> 3026 | K20: =VLOOKUP($F20,raw_data!$1:$1048576,MATCH(K$1,raw_data!$1:$1,0),FALSE) -> 2791 | L20: =VLOOKUP($F20,raw_data!$1:$1048576,MATCH(L$1,raw_data!$1:$1,0),FALSE) -> 3231 | M20: =VLOOKUP($F20,raw_data!$1:$1048576,MATCH(M$1,raw_data!$1:$1,0),FALSE) -> 973 | N20: =VLOOKUP($F20,raw_data!$1:$1048576,MATCH(N$1,raw_data!$1:$1,0),FALSE) -> 2478 | O20: =VLOOKUP($F20,raw_data!$1:$1048576,MATCH(O$1,raw_data!$1:$1,0),FALSE) -> 3997 | ... Q20: =VLOOKUP($F20,raw_data!$1:$1048576,MATCH(Q$1,raw_data!$1:$1,0),FALSE) -> 4989 | R20: =IFERROR(R2/R15,0) -> 5415.8827 | S20: =IFERROR(S2/S15,0) -> 5977.7727 | T20: =IFERROR(T2/T15,0) -> 6621.6367 | U20: =IFERROR(U2/U15,0) -> 7299.9418 | V20: =IFERROR(V2/V15,0) -> 8039.4004 | W20: =IFERROR(W2/W15,0) -> 8890.9776 | X20: =IFERROR(X2/X15,0) -> 9649.1527 | Y20: =IFERROR(Y2/Y15,0) -> 10499.734 | ... AU20: =IFERROR(AU2/AU15,0) -> 35100.705
C21: Maximum Takeoff Weight Per Aircraft(lb) | D21: float0 | F21: 대당최대이륙중량 | H21: =VLOOKUP($F21,raw_data!$1:$1048576,MATCH(H$1,raw_data!$1:$1,0),FALSE) -> 142380.25 | I21: =VLOOKUP($F21,raw_data!$1:$1048576,MATCH(I$1,raw_data!$1:$1,0),FALSE) -> 145631.9 | J21: =VLOOKUP($F21,raw_data!$1:$1048576,MATCH(J$1,raw_data!$1:$1,0),FALSE) -> 135888.96 | K21: =VLOOKUP($F21,raw_data!$1:$1048576,MATCH(K$1,raw_data!$1:$1,0),FALSE) -> 173211.75 | L21: =VLOOKUP($F21,raw_data!$1:$1048576,MATCH(L$1,raw_data!$1:$1,0),FALSE) -> 185967.19 | M21: =VLOOKUP($F21,raw_data!$1:$1048576,MATCH(M$1,raw_data!$1:$1,0),FALSE) -> 173379.24 | N21: =VLOOKUP($F21,raw_data!$1:$1048576,MATCH(N$1,raw_data!$1:$1,0),FALSE) -> 168314.77 | O21: =VLOOKUP($F21,raw_data!$1:$1048576,MATCH(O$1,raw_data!$1:$1,0),FALSE) -> 154574.43 | ... Q21: =VLOOKUP($F21,raw_data!$1:$1048576,MATCH(Q$1,raw_data!$1:$1,0),FALSE) -> 152140.31
C22: Average Aircraft Age(months) | D22: float0 | F22: 대당기령(월)평균
C23: Average Flight Distance(km) | D23: float0 | F23: 비행거리평균(km) | H23: =VLOOKUP($F23,raw_data!$1:$1048576,MATCH(H$1,raw_data!$1:$1,0),FALSE) -> 1272.1975 | I23: =VLOOKUP($F23,raw_data!$1:$1048576,MATCH(I$1,raw_data!$1:$1,0),FALSE) -> 1167.9195 | J23: =VLOOKUP($F23,raw_data!$1:$1048576,MATCH(J$1,raw_data!$1:$1,0),FALSE) -> 1170.3001 | K23: =VLOOKUP($F23,raw_data!$1:$1048576,MATCH(K$1,raw_data!$1:$1,0),FALSE) -> 1385.0777 | L23: =VLOOKUP($F23,raw_data!$1:$1048576,MATCH(L$1,raw_data!$1:$1,0),FALSE) -> 1459.5704 | M23: =VLOOKUP($F23,raw_data!$1:$1048576,MATCH(M$1,raw_data!$1:$1,0),FALSE) -> 1392.8181 | N23: =VLOOKUP($F23,raw_data!$1:$1048576,MATCH(N$1,raw_data!$1:$1,0),FALSE) -> 1349.27 | O23: =VLOOKUP($F23,raw_data!$1:$1048576,MATCH(O$1,raw_data!$1:$1,0),FALSE) -> 1572.2014 | ... Q23: =VLOOKUP($F23,raw_data!$1:$1048576,MATCH(Q$1,raw_data!$1:$1,0),FALSE) -> 1549.9844
C24: Payload Per Aircraft | D24: float0 | F24: 대당유상탑재중량 | H24: =VLOOKUP($F24,raw_data!$1:$1048576,MATCH(H$1,raw_data!$1:$1,0),FALSE) -> 8748.642 | I24: =VLOOKUP($F24,raw_data!$1:$1048576,MATCH(I$1,raw_data!$1:$1,0),FALSE) -> 15402.526 | J24: =VLOOKUP($F24,raw_data!$1:$1048576,MATCH(J$1,raw_data!$1:$1,0),FALSE) -> 13794.448 | K24: =VLOOKUP($F24,raw_data!$1:$1048576,MATCH(K$1,raw_data!$1:$1,0),FALSE) -> 21093.085 | L24: =VLOOKUP($F24,raw_data!$1:$1048576,MATCH(L$1,raw_data!$1:$1,0),FALSE) -> 18936.614 | M24: =VLOOKUP($F24,raw_data!$1:$1048576,MATCH(M$1,raw_data!$1:$1,0),FALSE) -> 18987.873 | N24: =VLOOKUP($F24,raw_data!$1:$1048576,MATCH(N$1,raw_data!$1:$1,0),FALSE) -> 16013.479 | O24: =VLOOKUP($F24,raw_data!$1:$1048576,MATCH(O$1,raw_data!$1:$1,0),FALSE) -> 18391.093 | ... Q24: =VLOOKUP($F24,raw_data!$1:$1048576,MATCH(Q$1,raw_data!$1:$1,0),FALSE) -> 23106.835
A25: Flight Class Index | B25: FleetMIx | C25: =C137&"FleetMix📝" -> (Widebody Jets급)FleetMix📝 | D25: percent1 | E25: O | F25: =C137&"혼합율" -> (Widebody Jets급)혼합율 | G25: =IFERROR(SUMIF($H$148:$Q$148,"O",H25:Q25)/COUNTIFS($H$148:$Q$148,"O",H25:Q25,"<>0"),0) -> 0.037309913 | H25: =VLOOKUP($F25,raw_data!$1:$1048576,MATCH(H$1,raw_data!$1:$1,0),FALSE) -> 0.015520282 | I25: =VLOOKUP($F25,raw_data!$1:$1048576,MATCH(I$1,raw_data!$1:$1,0),FALSE) -> 0.03933598 | J25: =VLOOKUP($F25,raw_data!$1:$1048576,MATCH(J$1,raw_data!$1:$1,0),FALSE) -> 0.02709848 | K25: =VLOOKUP($F25,raw_data!$1:$1048576,MATCH(K$1,raw_data!$1:$1,0),FALSE) -> 0.034754568 | L25: =IFERROR(VLOOKUP($F25,raw_data!$1:$1048576,MATCH(L$1,raw_data!$1:$1,0),FALSE),0) -> 0.05632931 | M25: =IFERROR(VLOOKUP($F25,raw_data!$1:$1048576,MATCH(M$1,raw_data!$1:$1,0),FALSE),0) -> 0.01336074 | N25: =IFERROR(VLOOKUP($F25,raw_data!$1:$1048576,MATCH(N$1,raw_data!$1:$1,0),FALSE),0) -> 0.023002421 | O25: =IFERROR(VLOOKUP($F25,raw_data!$1:$1048576,MATCH(O$1,raw_data!$1:$1,0),FALSE),0) -> 0.017513135 | P25: =IFERROR(VLOOKUP($F25,raw_data!$1:$1048576,MATCH(P$1,raw_data!$1:$1,0),FALSE),0) -> 0.03125 | Q25: =IFERROR(VLOOKUP($F25,raw_data!$1:$1048576,MATCH(Q$1,raw_data!$1:$1,0),FALSE),0) -> 0.020845861 | R25: =G25 -> 0.037309913 | S25: =R25 -> 0.037309913 | T25: =S25 -> 0.037309913 | U25: =T25 -> 0.037309913 | V25: =U25 -> 0.037309913 | W25: =V25 -> 0.037309913 | X25: =W25 -> 0.037309913 | Y25: =X25 -> 0.037309913 | Z25: =Y25 -> 0.037309913 | ... AU25: =AT25 -> 0.037309913
C26: =C138&"FleetMix📝" -> (Narrowbody Jets급)FleetMix📝 | D26: percent1 | E26: O | F26: =C138&"혼합율" -> (Narrowbody Jets급)혼합율 | G26: =IFERROR(SUMIF($H$148:$Q$148,"O",H26:Q26)/COUNTIFS($H$148:$Q$148,"O",H26:Q26,"<>0"),0) -> 0.96228921 | H26: =VLOOKUP($F26,raw_data!$1:$1048576,MATCH(H$1,raw_data!$1:$1,0),FALSE) -> 0.98447972 | I26: =VLOOKUP($F26,raw_data!$1:$1048576,MATCH(I$1,raw_data!$1:$1,0),FALSE) -> 0.96066402 | J26: =VLOOKUP($F26,raw_data!$1:$1048576,MATCH(J$1,raw_data!$1:$1,0),FALSE) -> 0.97290152 | K26: =VLOOKUP($F26,raw_data!$1:$1048576,MATCH(K$1,raw_data!$1:$1,0),FALSE) -> 0.96524543 | L26: =IFERROR(VLOOKUP($F26,raw_data!$1:$1048576,MATCH(L$1,raw_data!$1:$1,0),FALSE),0) -> 0.94367069 | M26: =IFERROR(VLOOKUP($F26,raw_data!$1:$1048576,MATCH(M$1,raw_data!$1:$1,0),FALSE),0) -> 0.98663926 | N26: =IFERROR(VLOOKUP($F26,raw_data!$1:$1048576,MATCH(N$1,raw_data!$1:$1,0),FALSE),0) -> 0.97699758 | O26: =IFERROR(VLOOKUP($F26,raw_data!$1:$1048576,MATCH(O$1,raw_data!$1:$1,0),FALSE),0) -> 0.98248687 | P26: =IFERROR(VLOOKUP($F26,raw_data!$1:$1048576,MATCH(P$1,raw_data!$1:$1,0),FALSE),0) -> 0.96821121 | Q26: =IFERROR(VLOOKUP($F26,raw_data!$1:$1048576,MATCH(Q$1,raw_data!$1:$1,0),FALSE),0) -> 0.97795149 | R26: =G26 -> 0.96228921 | S26: =R26 -> 0.96228921 | T26: =S26 -> 0.96228921 | U26: =T26 -> 0.96228921 | V26: =U26 -> 0.96228921 | W26: =V26 -> 0.96228921 | X26: =W26 -> 0.96228921 | Y26: =X26 -> 0.96228921 | Z26: =Y26 -> 0.96228921 | ... AU26: =AT26 -> 0.96228921
C27: =C139&"FleetMix📝" -> (Regional Jets급)FleetMix📝 | D27: percent1 | E27: O | F27: =C139&"혼합율" -> (Regional Jets급)혼합율 | G27: =IFERROR(SUMIF($H$148:$Q$148,"O",H27:Q27)/COUNTIFS($H$148:$Q$148,"O",H27:Q27,"<>0"),0) -> 0.0012026458 | H27: =VLOOKUP($F27,raw_data!$1:$1048576,MATCH(H$1,raw_data!$1:$1,0),FALSE) -> 0 | I27: =VLOOKUP($F27,raw_data!$1:$1048576,MATCH(I$1,raw_data!$1:$1,0),FALSE) -> 0 | J27: =VLOOKUP($F27,raw_data!$1:$1048576,MATCH(J$1,raw_data!$1:$1,0),FALSE) -> 0 | K27: =VLOOKUP($F27,raw_data!$1:$1048576,MATCH(K$1,raw_data!$1:$1,0),FALSE) -> 0 | L27: =IFERROR(VLOOKUP($F27,raw_data!$1:$1048576,MATCH(L$1,raw_data!$1:$1,0),FALSE),0) -> 0 | M27: =IFERROR(VLOOKUP($F27,raw_data!$1:$1048576,MATCH(M$1,raw_data!$1:$1,0),FALSE),0) -> 0 | N27: =IFERROR(VLOOKUP($F27,raw_data!$1:$1048576,MATCH(N$1,raw_data!$1:$1,0),FALSE),0) -> 0 | O27: =IFERROR(VLOOKUP($F27,raw_data!$1:$1048576,MATCH(O$1,raw_data!$1:$1,0),FALSE),0) -> 0 | P27: =IFERROR(VLOOKUP($F27,raw_data!$1:$1048576,MATCH(P$1,raw_data!$1:$1,0),FALSE),0) -> 0.0005387931 | Q27: =IFERROR(VLOOKUP($F27,raw_data!$1:$1048576,MATCH(Q$1,raw_data!$1:$1,0),FALSE),0) -> 0.0012026458 | R27: =G27 -> 0.0012026458 | S27: =R27 -> 0.0012026458 | T27: =S27 -> 0.0012026458 | U27: =T27 -> 0.0012026458 | V27: =U27 -> 0.0012026458 | W27: =V27 -> 0.0012026458 | X27: =W27 -> 0.0012026458 | Y27: =X27 -> 0.0012026458 | Z27: =Y27 -> 0.0012026458 | ... AU27: =AT27 -> 0.0012026458
C28: =C140&"FleetMix📝" -> (Business Jets급)FleetMix📝 | D28: percent1 | E28: O | F28: =C140&"혼합율" -> (Business Jets급)혼합율 | G28: =IFERROR(SUMIF($H$148:$Q$148,"O",H28:Q28)/COUNTIFS($H$148:$Q$148,"O",H28:Q28,"<>0"),0) -> 0 | H28: =IFERROR(VLOOKUP($F28,raw_data!$1:$1048576,MATCH(H$1,raw_data!$1:$1,0),FALSE),0) -> 0 | I28: =IFERROR(VLOOKUP($F28,raw_data!$1:$1048576,MATCH(I$1,raw_data!$1:$1,0),FALSE),0) -> 0 | J28: =IFERROR(VLOOKUP($F28,raw_data!$1:$1048576,MATCH(J$1,raw_data!$1:$1,0),FALSE),0) -> 0 | K28: =IFERROR(VLOOKUP($F28,raw_data!$1:$1048576,MATCH(K$1,raw_data!$1:$1,0),FALSE),0) -> 0 | L28: =IFERROR(VLOOKUP($F28,raw_data!$1:$1048576,MATCH(L$1,raw_data!$1:$1,0),FALSE),0) -> 0 | M28: =IFERROR(VLOOKUP($F28,raw_data!$1:$1048576,MATCH(M$1,raw_data!$1:$1,0),FALSE),0) -> 0 | N28: =IFERROR(VLOOKUP($F28,raw_data!$1:$1048576,MATCH(N$1,raw_data!$1:$1,0),FALSE),0) -> 0 | O28: =IFERROR(VLOOKUP($F28,raw_data!$1:$1048576,MATCH(O$1,raw_data!$1:$1,0),FALSE),0) -> 0 | ... Q28: =IFERROR(VLOOKUP($F28,raw_data!$1:$1048576,MATCH(Q$1,raw_data!$1:$1,0),FALSE),0) -> 0 | R28: =G28 -> 0 | S28: =R28 -> 0 | T28: =S28 -> 0 | U28: =T28 -> 0 | V28: =U28 -> 0 | W28: =V28 -> 0 | X28: =W28 -> 0 | Y28: =X28 -> 0 | Z28: =Y28 -> 0 | ... AU28: =AT28 -> 0
B29: Movements by Class | C29: =C137&"Movements" -> (Widebody Jets급)Movements | D29: float0 | F29: =C137&"운항횟수" -> (Widebody Jets급)운항횟수 | H29: =VLOOKUP($F29,raw_data!$1:$1048576,MATCH(H$1,raw_data!$1:$1,0),FALSE) -> 44 | I29: =VLOOKUP($F29,raw_data!$1:$1048576,MATCH(I$1,raw_data!$1:$1,0),FALSE) -> 109 | J29: =VLOOKUP($F29,raw_data!$1:$1048576,MATCH(J$1,raw_data!$1:$1,0),FALSE) -> 82 | K29: =VLOOKUP($F29,raw_data!$1:$1048576,MATCH(K$1,raw_data!$1:$1,0),FALSE) -> 97 | L29: =IFERROR(VLOOKUP($F29,raw_data!$1:$1048576,MATCH(L$1,raw_data!$1:$1,0),FALSE),0) -> 182 | M29: =IFERROR(VLOOKUP($F29,raw_data!$1:$1048576,MATCH(M$1,raw_data!$1:$1,0),FALSE),0) -> 13 | N29: =IFERROR(VLOOKUP($F29,raw_data!$1:$1048576,MATCH(N$1,raw_data!$1:$1,0),FALSE),0) -> 57 | O29: =IFERROR(VLOOKUP($F29,raw_data!$1:$1048576,MATCH(O$1,raw_data!$1:$1,0),FALSE),0) -> 70 | P29: =IFERROR(VLOOKUP($F29,raw_data!$1:$1048576,MATCH(P$1,raw_data!$1:$1,0),FALSE),0) -> 116 | Q29: =IFERROR(VLOOKUP($F29,raw_data!$1:$1048576,MATCH(Q$1,raw_data!$1:$1,0),FALSE),0) -> 104 | R29: =R20*R25 -> 202.06611 | S29: =S20*S25 -> 223.03018 | T29: =T20*T25 -> 247.05269 | U29: =U20*U25 -> 272.3602 | V29: =V20*V25 -> 299.94933 | W29: =W20*W25 -> 331.7216 | X29: =X20*X25 -> 360.00905 | Y29: =Y20*Y25 -> 391.74414 | ... AU29: =AU20*AU25 -> 1309.6042
C30: =C138&"Movements" -> (Narrowbody Jets급)Movements | D30: float0 | F30: =C138&"운항횟수" -> (Narrowbody Jets급)운항횟수 | H30: =VLOOKUP($F30,raw_data!$1:$1048576,MATCH(H$1,raw_data!$1:$1,0),FALSE) -> 2791 | I30: =VLOOKUP($F30,raw_data!$1:$1048576,MATCH(I$1,raw_data!$1:$1,0),FALSE) -> 2662 | J30: =VLOOKUP($F30,raw_data!$1:$1048576,MATCH(J$1,raw_data!$1:$1,0),FALSE) -> 2944 | K30: =VLOOKUP($F30,raw_data!$1:$1048576,MATCH(K$1,raw_data!$1:$1,0),FALSE) -> 2694 | L30: =IFERROR(VLOOKUP($F30,raw_data!$1:$1048576,MATCH(L$1,raw_data!$1:$1,0),FALSE),0) -> 3049 | M30: =IFERROR(VLOOKUP($F30,raw_data!$1:$1048576,MATCH(M$1,raw_data!$1:$1,0),FALSE),0) -> 960 | N30: =IFERROR(VLOOKUP($F30,raw_data!$1:$1048576,MATCH(N$1,raw_data!$1:$1,0),FALSE),0) -> 2421 | O30: =IFERROR(VLOOKUP($F30,raw_data!$1:$1048576,MATCH(O$1,raw_data!$1:$1,0),FALSE),0) -> 3927 | P30: =IFERROR(VLOOKUP($F30,raw_data!$1:$1048576,MATCH(P$1,raw_data!$1:$1,0),FALSE),0) -> 3594 | Q30: =IFERROR(VLOOKUP($F30,raw_data!$1:$1048576,MATCH(Q$1,raw_data!$1:$1,0),FALSE),0) -> 4879 | R30: =R20*R26 -> 5211.6455 | S30: =S20*S26 -> 5752.3462 | T30: =T20*T26 -> 6371.9295 | U30: =U20*U26 -> 7024.6552 | V30: =V20*V26 -> 7736.2282 | W30: =W20*W26 -> 8555.6917 | X30: =X20*X26 -> 9285.2755 | Y30: =Y20*Y26 -> 10103.78 | ... AU30: =AU20*AU26 -> 33777.029
C31: =C139&"Movements" -> (Regional Jets급)Movements | D31: float0 | F31: =C139&"운항횟수" -> (Regional Jets급)운항횟수 | H31: =VLOOKUP($F31,raw_data!$1:$1048576,MATCH(H$1,raw_data!$1:$1,0),FALSE) -> 0 | I31: =VLOOKUP($F31,raw_data!$1:$1048576,MATCH(I$1,raw_data!$1:$1,0),FALSE) -> 0 | J31: =VLOOKUP($F31,raw_data!$1:$1048576,MATCH(J$1,raw_data!$1:$1,0),FALSE) -> 0 | K31: =VLOOKUP($F31,raw_data!$1:$1048576,MATCH(K$1,raw_data!$1:$1,0),FALSE) -> 0 | L31: =IFERROR(VLOOKUP($F31,raw_data!$1:$1048576,MATCH(L$1,raw_data!$1:$1,0),FALSE),0) -> 0 | M31: =IFERROR(VLOOKUP($F31,raw_data!$1:$1048576,MATCH(M$1,raw_data!$1:$1,0),FALSE),0) -> 0 | N31: =IFERROR(VLOOKUP($F31,raw_data!$1:$1048576,MATCH(N$1,raw_data!$1:$1,0),FALSE),0) -> 0 | O31: =IFERROR(VLOOKUP($F31,raw_data!$1:$1048576,MATCH(O$1,raw_data!$1:$1,0),FALSE),0) -> 0 | P31: =IFERROR(VLOOKUP($F31,raw_data!$1:$1048576,MATCH(P$1,raw_data!$1:$1,0),FALSE),0) -> 2 | Q31: =IFERROR(VLOOKUP($F31,raw_data!$1:$1048576,MATCH(Q$1,raw_data!$1:$1,0),FALSE),0) -> 6 | R31: =R20*R27 -> 6.5133887 | S31: =S20*S27 -> 7.1891434 | T31: =T20*T27 -> 7.9634837 | U31: =U20*U27 -> 8.7792446 | V31: =V20*V27 -> 9.6685513 | W31: =W20*W27 -> 10.692697 | X31: =X20*X27 -> 11.604513 | Y31: =Y20*Y27 -> 12.627461 | ... AU31: =AU20*AU27 -> 42.213716
C32: =C140&"Movements" -> (Business Jets급)Movements | D32: float0 | F32: =C140&"운항횟수" -> (Business Jets급)운항횟수 | H32: =IFERROR(VLOOKUP($F32,raw_data!$1:$1048576,MATCH(H$1,raw_data!$1:$1,0),FALSE),0) -> 0 | I32: =IFERROR(VLOOKUP($F32,raw_data!$1:$1048576,MATCH(I$1,raw_data!$1:$1,0),FALSE),0) -> 0 | J32: =IFERROR(VLOOKUP($F32,raw_data!$1:$1048576,MATCH(J$1,raw_data!$1:$1,0),FALSE),0) -> 0 | K32: =IFERROR(VLOOKUP($F32,raw_data!$1:$1048576,MATCH(K$1,raw_data!$1:$1,0),FALSE),0) -> 0 | L32: =IFERROR(VLOOKUP($F32,raw_data!$1:$1048576,MATCH(L$1,raw_data!$1:$1,0),FALSE),0) -> 0 | M32: =IFERROR(VLOOKUP($F32,raw_data!$1:$1048576,MATCH(M$1,raw_data!$1:$1,0),FALSE),0) -> 0 | N32: =IFERROR(VLOOKUP($F32,raw_data!$1:$1048576,MATCH(N$1,raw_data!$1:$1,0),FALSE),0) -> 0 | O32: =IFERROR(VLOOKUP($F32,raw_data!$1:$1048576,MATCH(O$1,raw_data!$1:$1,0),FALSE),0) -> 0 | ... Q32: =IFERROR(VLOOKUP($F32,raw_data!$1:$1048576,MATCH(Q$1,raw_data!$1:$1,0),FALSE),0) -> 0 | R32: =R20*R28 -> 0 | S32: =S20*S28 -> 0 | T32: =T20*T28 -> 0 | U32: =U20*U28 -> 0 | V32: =V20*V28 -> 0 | W32: =W20*W28 -> 0 | X32: =X20*X28 -> 0 | Y32: =Y20*Y28 -> 0 | ... AU32: =AU20*AU28 -> 0
B33: MTOW by Class | C33: =C137&"MTOW" -> (Widebody Jets급)MTOW | D33: float0 | F33: =C137&"대당최대이륙중량" -> (Widebody Jets급)대당최대이륙중량 | G33: =IFERROR(SUMIF($H$158:$Q$158,"O",H33:Q33)/COUNTIFS($H$158:$Q$158,"O",H33:Q33,"<>0"),0) -> 431754.33 | H33: =VLOOKUP($F33,raw_data!$1:$1048576,MATCH(H$1,raw_data!$1:$1,0),FALSE) -> 398545.45 | I33: =VLOOKUP($F33,raw_data!$1:$1048576,MATCH(I$1,raw_data!$1:$1,0),FALSE) -> 448311.93 | J33: =VLOOKUP($F33,raw_data!$1:$1048576,MATCH(J$1,raw_data!$1:$1,0),FALSE) -> 434536.59 | K33: =VLOOKUP($F33,raw_data!$1:$1048576,MATCH(K$1,raw_data!$1:$1,0),FALSE) -> 412927.84 | L33: =VLOOKUP($F33,raw_data!$1:$1048576,MATCH(L$1,raw_data!$1:$1,0),FALSE) -> 408835.16 | M33: =VLOOKUP($F33,raw_data!$1:$1048576,MATCH(M$1,raw_data!$1:$1,0),FALSE) -> 374000 | N33: =VLOOKUP($F33,raw_data!$1:$1048576,MATCH(N$1,raw_data!$1:$1,0),FALSE) -> 391438.6 | O33: =VLOOKUP($F33,raw_data!$1:$1048576,MATCH(O$1,raw_data!$1:$1,0),FALSE) -> 377771.43 | ... Q33: =VLOOKUP($F33,raw_data!$1:$1048576,MATCH(Q$1,raw_data!$1:$1,0),FALSE) -> 473500 | R33: =G33 -> 431754.33 | S33: =R33 -> 431754.33 | T33: =S33 -> 431754.33 | U33: =T33 -> 431754.33 | V33: =U33 -> 431754.33 | W33: =V33 -> 431754.33 | X33: =W33 -> 431754.33 | Y33: =X33 -> 431754.33 | Z33: =Y33 -> 431754.33 | ... AU33: =AT33 -> 431754.33
C34: =C138&"MTOW" -> (Narrowbody Jets급)MTOW | D34: float0 | F34: =C138&"대당최대이륙중량" -> (Narrowbody Jets급)대당최대이륙중량 | G34: =IFERROR(SUMIF($H$158:$Q$158,"O",H34:Q34)/COUNTIFS($H$158:$Q$158,"O",H34:Q34,"<>0"),0) -> 160862.15 | H34: =VLOOKUP($F34,raw_data!$1:$1048576,MATCH(H$1,raw_data!$1:$1,0),FALSE) -> 138341.81 | I34: =VLOOKUP($F34,raw_data!$1:$1048576,MATCH(I$1,raw_data!$1:$1,0),FALSE) -> 133238.17 | J34: =VLOOKUP($F34,raw_data!$1:$1048576,MATCH(J$1,raw_data!$1:$1,0),FALSE) -> 127570.65 | K34: =VLOOKUP($F34,raw_data!$1:$1048576,MATCH(K$1,raw_data!$1:$1,0),FALSE) -> 164580.55 | L34: =VLOOKUP($F34,raw_data!$1:$1048576,MATCH(L$1,raw_data!$1:$1,0),FALSE) -> 172663.82 | M34: =VLOOKUP($F34,raw_data!$1:$1048576,MATCH(M$1,raw_data!$1:$1,0),FALSE) -> 170662.5 | N34: =VLOOKUP($F34,raw_data!$1:$1048576,MATCH(N$1,raw_data!$1:$1,0),FALSE) -> 163061.54 | O34: =VLOOKUP($F34,raw_data!$1:$1048576,MATCH(O$1,raw_data!$1:$1,0),FALSE) -> 150595.87 | ... Q34: =VLOOKUP($F34,raw_data!$1:$1048576,MATCH(Q$1,raw_data!$1:$1,0),FALSE) -> 145342.08 | R34: =G34 -> 160862.15 | S34: =R34 -> 160862.15 | T34: =S34 -> 160862.15 | U34: =T34 -> 160862.15 | V34: =U34 -> 160862.15 | W34: =V34 -> 160862.15 | X34: =W34 -> 160862.15 | Y34: =X34 -> 160862.15 | Z34: =Y34 -> 160862.15 | ... AU34: =AT34 -> 160862.15
C35: =C139&"MTOW" -> (Regional Jets급)MTOW | D35: float0 | F35: =C139&"대당최대이륙중량" -> (Regional Jets급)대당최대이륙중량 | G35: =IFERROR(SUMIF($H$158:$Q$158,"O",H35:Q35)/COUNTIFS($H$158:$Q$158,"O",H35:Q35,"<>0"),0) -> 110000 | H35: =VLOOKUP($F35,raw_data!$1:$1048576,MATCH(H$1,raw_data!$1:$1,0),FALSE) -> 0 | I35: =VLOOKUP($F35,raw_data!$1:$1048576,MATCH(I$1,raw_data!$1:$1,0),FALSE) -> 0 | J35: =VLOOKUP($F35,raw_data!$1:$1048576,MATCH(J$1,raw_data!$1:$1,0),FALSE) -> 0 | K35: =VLOOKUP($F35,raw_data!$1:$1048576,MATCH(K$1,raw_data!$1:$1,0),FALSE) -> 0 | L35: =VLOOKUP($F35,raw_data!$1:$1048576,MATCH(L$1,raw_data!$1:$1,0),FALSE) -> 0 | M35: =VLOOKUP($F35,raw_data!$1:$1048576,MATCH(M$1,raw_data!$1:$1,0),FALSE) -> 0 | N35: =VLOOKUP($F35,raw_data!$1:$1048576,MATCH(N$1,raw_data!$1:$1,0),FALSE) -> 0 | O35: =VLOOKUP($F35,raw_data!$1:$1048576,MATCH(O$1,raw_data!$1:$1,0),FALSE) -> 0 | ... Q35: =VLOOKUP($F35,raw_data!$1:$1048576,MATCH(Q$1,raw_data!$1:$1,0),FALSE) -> 110000 | R35: =G35 -> 110000 | S35: =R35 -> 110000 | T35: =S35 -> 110000 | U35: =T35 -> 110000 | V35: =U35 -> 110000 | W35: =V35 -> 110000 | X35: =W35 -> 110000 | Y35: =X35 -> 110000 | Z35: =Y35 -> 110000 | ... AU35: =AT35 -> 110000
C36: =C140&"MTOW" -> (Business Jets급)MTOW | D36: float0 | F36: =C140&"대당최대이륙중량" -> (Business Jets급)대당최대이륙중량 | G36: =IFERROR(SUMIF($H$158:$Q$158,"O",H36:Q36)/COUNTIFS($H$158:$Q$158,"O",H36:Q36,"<>0"),0) -> 0 | R36: =G36 -> 0 | S36: =R36 -> 0 | T36: =S36 -> 0 | U36: =T36 -> 0 | V36: =U36 -> 0 | W36: =V36 -> 0 | X36: =W36 -> 0 | Y36: =X36 -> 0 | Z36: =Y36 -> 0 | ... AU36: =AT36 -> 0
B37: Seats by Class | C37: =C137&"Seats" -> (Widebody Jets급)Seats | D37: float0 | F37: =C137&"대당좌석수" -> (Widebody Jets급)대당좌석수 | G37: =IFERROR(SUMIF($H$149:$Q$149,"O",H37:Q37)/COUNTIFS($H$149:$Q$149,"O",H37:Q37,"<>0"),0) -> 257.59264 | H37: =VLOOKUP($F37,raw_data!$1:$1048576,MATCH(H$1,raw_data!$1:$1,0),FALSE) -> 237.38636 | I37: =VLOOKUP($F37,raw_data!$1:$1048576,MATCH(I$1,raw_data!$1:$1,0),FALSE) -> 248.86239 | J37: =VLOOKUP($F37,raw_data!$1:$1048576,MATCH(J$1,raw_data!$1:$1,0),FALSE) -> 249.46341 | K37: =VLOOKUP($F37,raw_data!$1:$1048576,MATCH(K$1,raw_data!$1:$1,0),FALSE) -> 253.63918 | L37: =VLOOKUP($F37,raw_data!$1:$1048576,MATCH(L$1,raw_data!$1:$1,0),FALSE) -> 251.45604 | M37: =VLOOKUP($F37,raw_data!$1:$1048576,MATCH(M$1,raw_data!$1:$1,0),FALSE) -> 248.07692 | N37: =VLOOKUP($F37,raw_data!$1:$1048576,MATCH(N$1,raw_data!$1:$1,0),FALSE) -> 261.40351 | O37: =VLOOKUP($F37,raw_data!$1:$1048576,MATCH(O$1,raw_data!$1:$1,0),FALSE) -> 258.05714 | ... Q37: =VLOOKUP($F37,raw_data!$1:$1048576,MATCH(Q$1,raw_data!$1:$1,0),FALSE) -> 267.68269 | R37: =G37 -> 257.59264 | S37: =R37 -> 257.59264 | T37: =S37 -> 257.59264 | U37: =T37 -> 257.59264 | V37: =U37 -> 257.59264 | W37: =V37 -> 257.59264 | X37: =W37 -> 257.59264 | Y37: =X37 -> 257.59264 | Z37: =Y37 -> 257.59264 | ... AU37: =AT37 -> 257.59264
C38: =C138&"Seats" -> (Narrowbody Jets급)Seats | D38: float0 | F38: =C138&"대당좌석수" -> (Narrowbody Jets급)대당좌석수 | G38: =IFERROR(SUMIF($H$149:$Q$149,"O",H38:Q38)/COUNTIFS($H$149:$Q$149,"O",H38:Q38,"<>0"),0) -> 158.57558 | H38: =VLOOKUP($F38,raw_data!$1:$1048576,MATCH(H$1,raw_data!$1:$1,0),FALSE) -> 129.81799 | I38: =VLOOKUP($F38,raw_data!$1:$1048576,MATCH(I$1,raw_data!$1:$1,0),FALSE) -> 125.85011 | J38: =VLOOKUP($F38,raw_data!$1:$1048576,MATCH(J$1,raw_data!$1:$1,0),FALSE) -> 121.13451 | K38: =VLOOKUP($F38,raw_data!$1:$1048576,MATCH(K$1,raw_data!$1:$1,0),FALSE) -> 158.29399 | L38: =VLOOKUP($F38,raw_data!$1:$1048576,MATCH(L$1,raw_data!$1:$1,0),FALSE) -> 161.68711 | M38: =VLOOKUP($F38,raw_data!$1:$1048576,MATCH(M$1,raw_data!$1:$1,0),FALSE) -> 163.43229 | N38: =VLOOKUP($F38,raw_data!$1:$1048576,MATCH(N$1,raw_data!$1:$1,0),FALSE) -> 164.03511 | O38: =VLOOKUP($F38,raw_data!$1:$1048576,MATCH(O$1,raw_data!$1:$1,0),FALSE) -> 150.26076 | ... Q38: =VLOOKUP($F38,raw_data!$1:$1048576,MATCH(Q$1,raw_data!$1:$1,0),FALSE) -> 155.74564 | R38: =G38 -> 158.57558 | S38: =R38 -> 158.57558 | T38: =S38 -> 158.57558 | U38: =T38 -> 158.57558 | V38: =U38 -> 158.57558 | W38: =V38 -> 158.57558 | X38: =W38 -> 158.57558 | Y38: =X38 -> 158.57558 | Z38: =Y38 -> 158.57558 | ... AU38: =AT38 -> 158.57558
C39: =C139&"Seats" -> (Regional Jets급)Seats | D39: float0 | F39: =C139&"대당좌석수" -> (Regional Jets급)대당좌석수 | G39: =IFERROR(SUMIF($H$149:$Q$149,"O",H39:Q39)/COUNTIFS($H$149:$Q$149,"O",H39:Q39,"<>0"),0) -> 106 | H39: =VLOOKUP($F39,raw_data!$1:$1048576,MATCH(H$1,raw_data!$1:$1,0),FALSE) -> 0 | I39: =VLOOKUP($F39,raw_data!$1:$1048576,MATCH(I$1,raw_data!$1:$1,0),FALSE) -> 0 | J39: =VLOOKUP($F39,raw_data!$1:$1048576,MATCH(J$1,raw_data!$1:$1,0),FALSE) -> 0 | K39: =VLOOKUP($F39,raw_data!$1:$1048576,MATCH(K$1,raw_data!$1:$1,0),FALSE) -> 0 | L39: =VLOOKUP($F39,raw_data!$1:$1048576,MATCH(L$1,raw_data!$1:$1,0),FALSE) -> 0 | M39: =VLOOKUP($F39,raw_data!$1:$1048576,MATCH(M$1,raw_data!$1:$1,0),FALSE) -> 0 | N39: =VLOOKUP($F39,raw_data!$1:$1048576,MATCH(N$1,raw_data!$1:$1,0),FALSE) -> 0 | O39: =VLOOKUP($F39,raw_data!$1:$1048576,MATCH(O$1,raw_data!$1:$1,0),FALSE) -> 0 | ... Q39: =VLOOKUP($F39,raw_data!$1:$1048576,MATCH(Q$1,raw_data!$1:$1,0),FALSE) -> 106 | R39: =G39 -> 106 | S39: =R39 -> 106 | T39: =S39 -> 106 | U39: =T39 -> 106 | V39: =U39 -> 106 | W39: =V39 -> 106 | X39: =W39 -> 106 | Y39: =X39 -> 106 | Z39: =Y39 -> 106 | ... AU39: =AT39 -> 106
C40: =C140&"Seats" -> (Business Jets급)Seats | D40: float0 | F40: =C140&"대당좌석수" -> (Business Jets급)대당좌석수 | G40: =IFERROR(SUMIF($H$149:$Q$149,"O",H40:Q40)/COUNTIFS($H$149:$Q$149,"O",H40:Q40,"<>0"),0) -> 0 | R40: =G40 -> 0 | S40: =R40 -> 0 | T40: =S40 -> 0 | U40: =T40 -> 0 | V40: =U40 -> 0 | W40: =V40 -> 0 | X40: =W40 -> 0 | Y40: =X40 -> 0 | Z40: =Y40 -> 0 | ... AU40: =AT40 -> 0
...

Sheet raw_data
A1: KOR | B1: EN | C1: 2015 | D1: 2016 | E1: 2017 | F1: 2018 | G1: 2019 | H1: 2020 | I1: 2021 | J1: 2022 | K1: 2023 | L1: 2024
A2: 연간여객 | B2: annual_passengers | C2: 317549 | D2: 296385 | E2: 300529 | F2: 360857 | G2: 427585 | H2: 119957 | I2: 336251 | J2: 503019 | K2: 493777 | L2: 601530
A3: International여객 | B3: international_passengers | C3: 125299 | D3: 103500 | E3: 117081 | F3: 162463 | G3: 212440 | H3: 54451 | I3: 174174 | J3: 298727 | K3: 265902 | L3: 318069
A4: Domestic여객 | B4: domestic_passengers | C4: 192250 | D4: 192885 | E4: 183448 | F4: 198394 | G4: 215145 | H4: 65506 | I4: 162077 | J4: 204292 | K4: 227875 | L4: 283461
A5: Long_haul여객 | B5: long_haul_passengers | C5: 4469 | D5: 7174 | E5: 7308 | F5: 5646 | G5: 11025 | H5: 0 | I5: 0 | J5: 3387 | K5: 8780 | L5: 13587
A6: Short_haul여객 | B6: short_haul_passengers | C6: 313080 | D6: 289211 | E6: 293221 | F6: 355211 | G6: 416560 | H6: 119957 | I6: 336251 | J6: 499632 | K6: 484997 | L6: 587943
A7: 정규여객 | B7: scheduled_passengers | C7: 317549 | D7: 296385 | E7: 300529 | F7: 360857 | G7: 427585 | H7: 119957 | I7: 336251 | J7: 503019 | K7: 493777 | L7: 601530
A8: 전세기여객 | B8: charter_passengers | C8: 0 | D8: 0 | E8: 0 | F8: 0 | G8: 0 | H8: 0 | I8: 0 | J8: 0 | K8: 0 | L8: 0
A9: 연간OD여객 | B9: annual_od_passengers | C9: 298953 | D9: 282010 | E9: 289205 | F9: 351296 | G9: 417084 | H9: 117998 | I9: 324976 | J9: 486433 | K9: 485051 | L9: 583227
A10: 연간환승승객 | B10: annual_transfer_passengers | C10: 18596 | D10: 14375 | E10: 11324 | F10: 9561 | G10: 10501 | H10: 1959 | I10: 11275 | J10: 16586 | K10: 8726 | L10: 18303
A11: 연간승무원 | B11: annual_crew | C11: 20274 | D11: 18708 | E11: 18760 | F11: 23621 | G11: 27147 | H11: 7780 | I11: 21444 | J11: 32512 | K11: 31869 | L11: 38429
A12: 연간운항 | B12: annual_movements | C12: 2835 | D12: 2771 | E12: 3026 | F12: 2791 | G12: 3231 | H12: 973 | I12: 2478 | J12: 3997 | K12: 3712 | L12: 4989
... A37: 대당유상탑재중량 | B37: payload_per_aircraft | C37: 8748.642 | D37: 15402.526 | E37: 13794.448 | F37: 21093.085 | G37: 18936.614 | H37: 18987.873 | I37: 16013.479 | J37: 18391.093 | K37: 24565.248 | L37: 23106.835
A38: 피크시간 턴어라운드편 평균주기시간(분) | B38: peak_turnaround_cycle_time_min
A39: 피크시간 턴어라운드편 평균그라운드시간(분) | B39: peak_turnaround_ground_time_min
A40: 턴어라운드편 평균주기시간(분) | B40: avg_turnaround_cycle_time_min
A41: 턴어라운드편 평균그라운드시간(분) | B41: avg_turnaround_ground_time_min
A42: (오버나잇, 소산 포함) 피크시간 평균주기시간(분) | B42: peak_cycle_time_with_overnight_dispersion_min
A43: (오버나잇, 소산 포함) 평균주기시간(분) | B43: avg_cycle_time_with_overnight_dispersion_min
A44: (오버나잇, 소산 포함) 평균그라운드시간(분) | B44: avg_ground_time_with_overnight_dispersion_min
A45: (Narrowbody Jets급)운항횟수 | B45: narrowbody_movements | C45: 2791 | D45: 2662 | E45: 2944 | F45: 2694 | G45: 3049 | H45: 960 | I45: 2421 | J45: 3927 | K45: 3594 | L45: 4879
A46: (Narrowbody Jets급)혼합율 | B46: narrowbody_mix_ratio | C46: 0.98447972 | D46: 0.96066402 | E46: 0.97290152 | F46: 0.96524543 | G46: 0.94367069 | H46: 0.98663926 | I46: 0.97699758 | J46: 0.98248687 | K46: 0.96821121 | L46: 0.97795149
A47: (Narrowbody Jets급)대당좌석수 | B47: narrowbody_seats_per_aircraft | C47: 129.81799 | D47: 125.85011 | E47: 121.13451 | F47: 158.29399 | G47: 161.68711 | H47: 163.43229 | I47: 164.03511 | J47: 150.26076 | K47: 160.21202 | L47: 155.74564
A48: (Narrowbody Jets급)대당여객 | B48: narrowbody_passengers_per_aircraft | C48: 110.74884 | D48: 103.57363 | E48: 96.965353 | F48: 128.0464 | G48: 130.55297 | H48: 122.5 | I48: 134.48286 | J48: 124.40565 | K48: 131.25849 | L48: 119.35807
A49: (Narrowbody Jets급)탑승율 | B49: narrowbody_load_factor | C49: 0.85310856 | D49: 0.82299194 | E49: 0.8004767 | F49: 0.80891512 | G49: 0.80744203 | H49: 0.74954587 | I49: 0.81984192 | J49: 0.82793175 | K49: 0.81927989 | L49: 0.76636535
A50: (Narrowbody Jets급)환승율 | B50: narrowbody_transfer_rate | C50: 0.057968295 | D50: 0.048445304 | E50: 0.037612185 | F50: 0.026736666 | G50: 0.024408626 | H50: 0.016190476 | I50: 0.030772491 | J50: 0.032865205 | K50: 0.017530732 | L50: 0.03033753
A51: (Narrowbody Jets급)대당환승승객 | B51: narrowbody_transfer_passengers_per_aircraft | C51: 6.4199212 | D51: 5.0176559 | E51: 3.6470788 | F51: 3.4235338 | G51: 3.1866186 | H51: 1.9833333 | I51: 4.1383726 | J51: 4.0886173 | K51: 2.3010573 | L51: 3.6210289
A52: (Narrowbody Jets급)대당승무원 | B52: narrowbody_crew_per_aircraft | C52: 7.0677177 | D52: 6.5097671 | E52: 6.0424592 | F52: 8.3834447 | G52: 8.2715644 | H52: 7.946875 | I52: 8.5658819 | J52: 8.0407436 | K52: 8.4752365 | L52: 7.6179545
A53: (Narrowbody Jets급)승무원비율 | B53: narrowbody_crew_ratio | C53: 0.063817535 | D53: 0.062851588 | E53: 0.062315652 | F53: 0.065471928 | G53: 0.063357919 | H53: 0.064872449 | I53: 0.063694972 | J53: 0.064633265 | K53: 0.064569056 | L53: 0.06382438
A54: (Narrowbody Jets급)명당수하물 | B54: narrowbody_baggage_per_passenger | C54: 12.3 | D54: 12.3 | E54: 12.3 | F54: 12.3 | G54: 12.3 | H54: 12.3 | I54: 12.3 | J54: 12.3 | K54: 12.3 | L54: 12.3
A55: (Narrowbody Jets급)대당최대이륙중량 | B55: narrowbody_mtow_per_aircraft | C55: 138341.81 | D55: 133238.17 | E55: 127570.65 | F55: 164580.55 | G55: 172663.82 | H55: 170662.5 | I55: 163061.54 | J55: 150595.87 | K55: 160853.64 | L55: 145342.08
A56: (Narrowbody Jets급)대당택싱평균 | B56: narrowbody_avg_taxi_time | C56: 0 | D56: 0 | E56: 0 | F56: 0 | G56: 0 | H56: 0 | I56: 0 | J56: 0 | K56: 0 | L56: 0
... A72: (Widebody Jets급)대당유상탑재중량 | B72: widebody_payload_per_aircraft | C72: 48727.273 | D72: 52333.945 | E72: 43600 | F72: 30602.062 | G72: 32528.571 | H72: 25400 | I72: 30164.912 | J72: 26971.429 | K72: 41896.552 | L72: 62971.154
A73: SBR/시작(N번째) | B73: sbr_start_n | C73: 140번째 | D73: 140번째 | E73: 140번째 | F73: 140번째 | G73: 140번째 | H73: 140번째 | I73: 140번째 | J73: 140번째 | K73: 140번째 | L73: 140번째
A74: SBR/종료(N번째) | B74: sbr_end_n | C74: 160번째 | D74: 160번째 | E74: 160번째 | F74: 160번째 | G74: 160번째 | H74: 160번째 | I74: 160번째 | J74: 160번째 | K74: 160번째 | L74: 160번째
A75: ADPM/movement/all/H팩터 | B75: adpm_movement_all_h_factor | C75: 4 | D75: 4.7 | E75: 4.7 | F75: 5.7666667 | G75: 4.175 | H75: 0 | I75: 6.175 | J75: 6.2866667 | K75: 6.1333333 | L75: 6.8333333
A76: ADPM/movement/all/D팩터 | B76: adpm_movement_all_d_factor | C76: 320.25 | D76: 327.28346 | E76: 318.25172 | F76: 297.64161 | G76: 292.85438 | H76: 0 | I76: 231.12844 | J76: 327.53194 | K76: 321.87972 | L76: 297.77789
A77: ADPM/movement/all/PHF | B77: adpm_movement_all_phf | C77: 0.00078064012 | D77: 0.00065009687 | E77: 0.00066854613 | F77: 0.00058261479 | G77: 0.00081788415 | H77: 0 | I77: 0.00070066375 | J77: 0.00048565281 | K77: 0.00050653542 | L77: 0.00049144503
A78: ADPM/movement/all/첨두시 | B78: adpm_movement_all_peak_hour | C78: 2.2131148 | D78: 1.8014184 | E78: 2.0230206 | F78: 1.6260779 | G78: 2.6425837 | H78: 0 | I78: 1.7362448 | J78: 1.9411543 | K78: 1.8802595 | L78: 2.4518193
A79: SBR/movement/all/PHF | B79: sbr_movement_all_phf | C79: 0.00070546737 | D79: 0.0007217611 | E79: 0.00066093853 | F79: 0.00071658904 | G79: 0.0006190034 | H79: 0.0010277492 | I79: 0.0008071025 | J79: 0.00050037528 | K79: 0.0005387931 | L79: 0.0005917781
...

Sheet ref
A2: airport_iata_code_list | B2: ['UGC']
A3: start_year | B3: 2015
A4: end_year | B4: 2024
A5: predict_end_year | B5: 2051
B12: 2015 | C12: 2016 | D12: 2017 | E12: 2018 | F12: 2019 | G12: 2020 | H12: 2021 | I12: 2022 | J12: 2023 | K12: 2024
A13: Demand | B13: FALSE | C13: FALSE | D13: FALSE | E13: TRUE | F13: TRUE | G13: FALSE | H13: FALSE | I13: FALSE | J13: FALSE | K13: TRUE
A14: Load_Factor | B14: FALSE | C14: FALSE | D14: FALSE | E14: TRUE | F14: TRUE | G14: FALSE | H14: FALSE | I14: FALSE | J14: FALSE | K14: TRUE
A15: Transfer_Rate | B15: FALSE | C15: FALSE | D15: FALSE | E15: TRUE | F15: TRUE | G15: FALSE | H15: FALSE | I15: FALSE | J15: FALSE | K15: TRUE
A16: FleetMix_Rate | B16: FALSE | C16: FALSE | D16: FALSE | E16: TRUE | F16: TRUE | G16: FALSE | H16: FALSE | I16: FALSE | J16: FALSE | K16: TRUE
A17: Seats_Per_Aircraft | B17: FALSE | C17: FALSE | D17: FALSE | E17: TRUE | F17: TRUE | G17: FALSE | H17: FALSE | I17: FALSE | J17: FALSE | K17: TRUE
A18: Load_Factor_By_Class | B18: FALSE | C18: FALSE | D18: FALSE | E18: TRUE | F18: TRUE | G18: FALSE | H18: FALSE | I18: FALSE | J18: FALSE | K18: TRUE
A19: Transfer_Rate_By_Class | B19: FALSE | C19: FALSE | D19: FALSE | E19: TRUE | F19: TRUE | G19: FALSE | H19: FALSE | I19: FALSE | J19: FALSE | K19: TRUE
A20: Crew_Per_Aircraft | B20: FALSE | C20: FALSE | D20: FALSE | E20: TRUE | F20: TRUE | G20: FALSE | H20: FALSE | I20: FALSE | J20: FALSE | K20: TRUE
A21: Movement_PHF_Adjustment | B21: FALSE | C21: FALSE | D21: FALSE | E21: TRUE | F21: TRUE | G21: FALSE | H21: FALSE | I21: FALSE | J21: FALSE | K21: TRUE
A22: Movement_D_Factor | B22: FALSE | C22: FALSE | D22: FALSE | E22: TRUE | F22: TRUE | G22: FALSE | H22: FALSE | I22: FALSE | J22: FALSE | K22: TRUE
A23: Passenger_PHF_Adjustment | B23: FALSE | C23: FALSE | D23: FALSE | E23: TRUE | F23: TRUE | G23: FALSE | H23: FALSE | I23: FALSE | J23: FALSE | K23: TRUE
A24: Passenger_D_Factor | B24: FALSE | C24: FALSE | D24: FALSE | E24: TRUE | F24: TRUE | G24: FALSE | H24: FALSE | I24: FALSE | J24: FALSE | K24: TRUE
... A27: PeakTime Standing | B27: FALSE | C27: FALSE | D27: FALSE | E27: TRUE | F27: TRUE | G27: FALSE | H27: FALSE | I27: FALSE | J27: FALSE | K27: TRUE

Sheet Reg (total_passenger)
B1: GDP per capita | C1: Working-age Population | D1: COVID19 | E1: regression
A2: 2015 | B2: 7463.5 | C2: 21015278 | D2: 0 | E2: 317549 | F2: 7463.5
A3: 2016 | B3: 7767.8 | C3: 21308256 | D3: 0 | E3: 296385 | F3: =F2*1.035 -> 7724.7225
A4: 2017 | B4: 7971.6 | C4: 21583420 | D4: 0 | E4: 300529 | F4: =F3*1.035 -> 7995.0878 | H4: =4.5/3.5 -> 1.2857143
A5: 2018 | B5: 8276.6 | C5: 21843170 | D5: 0 | E5: 360857 | F5: =F4*1.035 -> 8274.9159
A6: 2019 | B6: 8678.6 | C6: 22105578 | D6: 0 | E6: 427585 | F6: =F5*1.035 -> 8564.5379
A7: 2020 | B7: 8645.3 | C7: 22374882 | D7: 1 | E7: 119957 | F7: =F6*1.035 -> 8864.2967
A8: 2021 | B8: 9163.3 | C8: 22676383 | D8: 0.2 | E8: 336251 | F8: =F7*1.035 -> 9174.5471
A9: 2022 | B9: 9517 | C9: 23047260 | D9: 0.2 | E9: 503019 | F9: =F8*1.035 -> 9495.6563
A10: 2023 | B10: 9904.2 | C10: 23479159 | D10: 0 | E10: 493899 | F10: =F9*1.035 -> 9828.0042
A11: 2024 | B11: 10204.9 | C11: 23785528 | D11: 0 | E11: 601405 | F11: =F10*1.035 -> 10171.984
A12: 2025 | B12: 10565.6 | C12: 24088446 | D12: 0 | E12: 609581 | F12: =F11*1.035 -> 10528.004
A13: 2026 | B13: 10937.7 | C13: 24377779 | D13: 0 | E13: 658766 | F13: =F12*1.035 -> 10896.484
A14: 2027 | B14: 11323.4 | C14: 24661828 | D14: 0 | E14: 711583 | F14: =F13*1.035 -> 11277.861
A15: 2028 | B15: 11722.9 | C15: 24959387 | D15: 0 | E15: 765903 | F15: =F14*1.035 -> 11672.586
A16: 2029 | B16: 12136.5 | C16: 25279029 | D16: 0 | E16: 820800 | F16: =F15*1.035 -> 12081.127
... A22: 2035 | B22: 14475.116 | C22: 27524241 | D22: 0 | E22: 1080539 | F22: =F21*1.035 -> 14850.789
A23: 2036 | B23: 14881.779 | C23: 27944126 | D23: 0 | E23: 1122296 | F23: =F22*1.03 -> 15296.313
A24: 2037 | B24: 15293.487 | C24: 28325367 | D24: 0 | E24: 1169645 | F24: =F23*1.03 -> 15755.202
A25: 2038 | B25: 15709.815 | C25: 28673129 | D25: 0 | E25: 1221895 | F25: =F24*1.03 -> 16227.858
A26: 2039 | B26: 16130.788 | C26: 28986910 | D26: 0 | E26: 1279108 | F26: =F25*1.03 -> 16714.694
A27: 2040 | B27: 16556.85 | C27: 29268069 | D27: 0 | E27: 1341226 | F27: =F26*1.03 -> 17216.135
A28: 2041 | B28: 16987.7 | C28: 29520378 | D28: 0 | E28: 1407746 | F28: =F27*1.03 -> 17732.619
A29: 2042 | B29: 17422.771 | C29: 29747651 | D29: 0 | E29: 1478100 | F29: =F28*1.03 -> 18264.597
A30: 2043 | B30: 17861.889 | C30: 29957984 | D30: 0 | E30: 1551314 | F30: =F29*1.03 -> 18812.535
A31: 2044 | B31: 18305.279 | C31: 30152252 | D31: 0 | E31: 1627335 | F31: =F30*1.03 -> 19376.911
A32: 2045 | B32: 18752.034 | C32: 30331171 | D32: 0 | E32: 1705880 | F32: =F31*1.03 -> 19958.219
A33: 2046 | B33: 19201.903 | C33: 30496862 | D33: 0 | E33: 1786647 | F33: =F32*1.03 -> 20556.965
A34: 2047 | B34: 19655.138 | C34: 30646766 | D34: 0 | E34: 1869989 | F34: =F33*1.03 -> 21173.674
... A40: 2053 | B40: 22486.14 | C40: 31293606 | D40: 0 | E40: 2424055 | F40: =F39*1.03 -> 25282.474
A41: 2054 | B41: 22985.753 | C41: 31393407 | D41: 0 | E41: 2523497 | F41: =F40*1.03 -> 26040.949 | H41: =E41*1.3 -> 3280546.1
A42: 2055 | B42: 23496.226 | C42: 31493526 | D42: 0 | E42: 2625315 | F42: =F41*1.03 -> 26822.177
A43: 2056 | B43: 24019.143 | C43: 31593965 | D43: 0 | E43: 2729860 | F43: =F42*1.03 -> 27626.843
A44: 2057 | B44: 24555.92 | C44: 31694724 | D44: 0 | E44: 2837447 | F44: =F43*1.03 -> 28455.648
A45: 2058 | B45: 25106.678 | C45: 31795804 | D45: 0 | E45: 2948103 | F45: =F44*1.03 -> 29309.317
A46: 2059 | B46: 25670.273 | C46: 31897206 | D46: 0 | E46: 3061573 | F46: =F45*1.03 -> 30188.597
A47: 2060 | B47: 26246.768 | C47: 31998932 | D47: 0 | E47: 3177872 | F47: =F46*1.03 -> 31094.255

Sheet Country Ratio (total_passenger)
B1: airport_real | C1: country_pred | D1: ratio | E1: country ratio
A2: 2015 | B2: 317549 | C2: 4274801 | D2: 0.074283926 | E2: 317549
A3: 2016 | B3: 296385 | C3: 4015174 | D3: 0.073816228 | E3: 296385
A4: 2017 | B4: 300529 | C4: 4344127 | D4: 0.069180528 | E4: 300529
A5: 2018 | B5: 360857 | C5: 5227993 | D5: 0.069024002 | E5: 360857
A6: 2019 | B6: 427585 | C6: 6421627 | D6: 0.06658515 | E6: 427585
A7: 2020 | B7: 119957 | D7: 0.06658515 | E7: 119957
A8: 2021 | B8: 336251 | D8: 0.06658515 | E8: 336251
A9: 2022 | B9: 503019 | C9: 6518515 | D9: 0.077167729 | E9: 503019
A10: 2023 | B10: 493899 | C10: 7286530 | D10: 0.06778247 | E10: 493899
A11: 2024 | B11: 601405 | C11: 7721512 | D11: 0.09 | E11: =C11*D11 -> 694936.08
A12: 2025 | C12: 8272809 | D12: 0.09 | E12: =C12*D12 -> 744552.81
A13: 2026 | C13: 8889600 | D13: 0.09 | E13: =C13*D13 -> 800064
A14: 2027 | C14: 9517063 | D14: 0.09 | E14: =C14*D14 -> 856535.67
A15: 2028 | C15: 10174388 | D15: 0.09 | E15: =C15*D15 -> 915694.92
A16: 2029 | C16: 10877594 | D16: 0.09 | E16: =C16*D16 -> 978983.46
A17: 2030 | C17: 11622038 | D17: 0.09 | E17: =C17*D17 -> 1045983.4
A18: 2031 | C18: 12380233 | D18: 0.09 | E18: =C18*D18 -> 1114221
A19: 2032 | C19: 13127388 | D19: 0.09 | E19: =C19*D19 -> 1181464.9
A20: 2033 | C20: 13880818 | D20: 0.09 | E20: =C20*D20 -> 1249273.6
A21: 2034 | C21: 14631335 | D21: 0.09 | E21: =C21*D21 -> 1316820.1
A22: 2035 | C22: 15377925 | D22: 0.09 | E22: =C22*D22 -> 1384013.2
A23: 2036 | C23: 16121934 | D23: 0.09 | E23: =C23*D23 -> 1450974.1
... A39: 2052 | C39: 27365549 | D39: 0.09 | E39: =C39*D39 -> 2462899.4
